Workbook

Sheet Settings
A1: Global Settings & Defaults
A2: Parameter | B2: Value | C2: True Cost | D2: Notes
A3: canopy_height_default_ft | B3: 16.5 | D3: Standard canopy height. 20 ft is blocked by configurator.
A4: default_dispensers | B4: 4 | D4: Initial dispenser count shown to user.
A5: default_overhang_ft | B5: 10 | D5: Overhang each side. Used in width formula.
A6: default_distance_dive_in_ft | B6: 28 | D6: Default distance between dispensers (Dive-in).
A7: default_distance_stacked_ft | B7: 28 | D7: Default distance per row (Stacked).
A8: default_distance_in_line_ft | B8: 20 | D8: Default distance (In-line).
A9: depth_dive_in_ft | B9: 24 | D9: Fixed depth for Dive-in.
A10: depth_stacked_ft | B10: 48 | D10: Fixed depth for Stacked (2 rows).
A11: depth_in_line_ft | B11: 24 | D11: Fixed depth for In-line.
A12: acm_panel_width_ft | B12: 10 | D12: Panel width — used in ACM formula.
A13: tax_default_rate | B13: 0.0825 | D13: Default sales tax rate.
A14: laborer_count | B14: 4 | D14: Number of laborers per crew.
A15: hours_per_day | B15: 10 | D15: Hours per laborer per day.
A16: hourly_rate | B16: 30 | C16: (value is cost) | D16: Dollar rate per laborer-hour.
A17: labor_daily_rate | B17: =B14*B15*B16 | C17: (value is cost) | D17: Derived: laborer_count × hours × rate. Should equal $1,200/day.
A18: branded_labor_adder | B18: 2800 | D18: Added to labor when canopy is Branded. Sold AT COST (no GP markup).
A19: two_disp_labor_adder | B19: 5000 | D19: Added when dispensers = 2. Sold AT COST (no GP markup).
A20: shipping_handling | B20: 3500 | D20: Added to MISC when branded. Sold AT COST — this $3,500 IS the markup.

Sheet Material_Rates
A1: Material Unit Rates
A2: Parameter | B2: Selling | C2: True Cost | D2: Notes
A3: acm_per_panel | B3: 450 | D3: Per 10-ft ACM panel. Marked up at GP (when Unbranded only).
A4: steel_primary_per_col | B4: 4000 | D4: Standard column. Marked up at GP.
A5: steel_secondary_per_col | B5: 2000 | D5: Second-set column on double-col Dive-in. Sold AT COST.
A6: decking_per_col | B6: 5000 | D6: Per column. Marked up at GP.
A7: light_unit_price | B7: 150 | D7: Per light. Marked up at GP.

Sheet MISC_Tiers
A1: MISC Pricing — Tiered by Column Count
A2: cols_low | B2: cols_high | C2: selling | D2: true_cost | E2: notes
A3: 1 | B3: 4 | C3: 2500 | E3: Paint, Transportation, Insurance, PM, Shipping & Handling base
A4: 5 | B4: 8 | C4: 4000
A5: 9 | B5: 12 | C5: 6000

Sheet Labor_Days
A1: Labor Days by Dispenser Count
A2: dispensers | B2: days | C2: base_labor_$
A3: 2 | B3: 3 | C3: =B3*Settings!B17
A4: 3 | B4: 5 | C4: =B4*Settings!B17
A5: 4 | B5: 7 | C5: =B5*Settings!B17
A6: 5 | B6: 10 | C6: =B6*Settings!B17
A7: 6 | B7: 12 | C7: =B7*Settings!B17
A8: 7 | B8: 12 | C8: =B8*Settings!B17
A9: 8 | B9: 14 | C9: =B9*Settings!B17
A10: 9 | B10: 15 | C10: =B10*Settings!B17
A11: 10 | B11: 15 | C11: =B11*Settings!B17
A13: Note: | B13: Base labor IS the true cost (4×10×$30). Markup happens via × (1+GP).

Sheet Brand_Imaging
A1: Brand Imaging — pass-through AT COST (no markup, no profit). Profit lives in shipping.
A2: brand | B2: 2_disp | C2: 3_disp | D2: 4_disp | E2: 5_disp | F2: 6_disp | G2: 7_disp | H2: 8_disp | I2: 9_disp | J2: 10_disp | K2: notes
A3: Chevron Level I | B3: 14780 | C3: 21420 | D3: 28786 | E3: 35101 | F3: 42181 | K3: 7+ disp prices needed.
A4: Valero | B4: 15480 | C4: 18990 | D4: 25860 | E4: 33301 | F4: 35741 | K4: 7+ disp prices needed.
A5: Shell | B5: 11280 | C5: 16920 | D5: 22560 | E5: 28201 | F5: 33841 | K5: 7+ disp prices needed.
A6: Exxon | K6: Jobber-supplied — declare not included.
A7: BP | K7: Jobber-supplied — declare not included.
A8: Marathon | K8: Jobber-supplied — confirm: jobber or add prices?
A9: Citgo | K9: Jobber-supplied — confirm: jobber or add prices?
A11: Note: | B11: Brand imaging is a pure pass-through. We charge what it costs us. Our profit on branded jobs comes from the $3,500 shipping markup (vs actual freight cost), not from imaging.

Sheet MID_PriceSign
A1: MID / Price Sign Material — sold AT COST (no GP markup), tax applies
A2: brand | B2: selling | C2: true_cost | D2: notes
A3: Shell | B3: 27548
A4: Chevron C45 | B4: 26000
A5: Chevron C60 | B5: 34548
A6: Valero | B6: 27000
A7: Unbranded | B7: 25000 | D7: Default if no brand chosen.

Sheet MID_Labor
A1: MID Labor — packaged at-cost (no markup), tax-exempt (it's labor)
A2: state | B2: selling | C2: true_cost | D2: notes
A3: GA | B3: 11000 | D3: Georgia rate.
A4: TX | B4: 9000 | D4: Texas rate.
A5: (other) | B5: custom | D5: If state ≠ GA/TX, configurator prompts user for custom amount.

Sheet Salespeople
A1: Sales People — auto-fills phone & email on proposal
A2: name | B2: phone | C2: email
A3: Walid Bayoumi | B3: 770-296-6418 | C3: walid@TheAPECgroup.com
A4: Arash Husain | B4: 770-680-3416 | C4: arash@GeoPetroleum.com
A5: Kamal Budhwani | B5: 346-863-2104 | C5: kamal@GeoPetroleum.com

Sheet Markup_Rules
A1: Markup & Tax Rules (documentation — configurator does not read this)
A2: line_item | B2: marked_up? | C2: tax_applies? | D2: notes
A3: ACM | B3: Yes (only if Unbranded) | C3: Yes | D3: When canopy is Branded, ACM is NOT charged — covered in Brand Imaging.
A4: Steel — first set ($4,000/col) | B4: Yes | C4: Yes
A5: Steel — second set ($2,000/col) | B5: No | C5: Yes | D5: Double-col Dive-in only. Sold AT COST.
A6: Decking | B6: Yes | C6: Yes
A7: Lights | B7: Yes | C7: Yes
A8: MISC base | B8: Yes | C8: Yes
A9: Brand imaging material (cheat sheet) | B9: No | C9: Yes | D9: Sold AT COST.
A10: Shipping & handling ($3,500) | B10: No | C10: Yes | D10: Applies when Branded. The $3,500 IS the markup.
A11: MID material (price-sign cheat sheet) | B11: No | C11: Yes | D11: Sold AT COST.
A12: Base labor | B12: Yes | C12: No | D12: Tax-exempt — it's labor.
A13: Branded labor adder ($2,800) | B13: No | C13: No | D13: Sold AT COST. Tax-exempt.
A14: 2-dispenser labor adder ($5,000) | B14: No | C14: No | D14: Sold AT COST. Tax-exempt.
A15: MID labor (GA $11k / TX $9k / Custom) | B15: No | C15: No | D15: Pre-packaged at cost. Tax-exempt.

Sheet Internal_PL
A1: Internal P&L — Owner Only
A2: Hidden tab. Password 'cheap' to unhide.
A4: PRICING LEVERS (moved from Settings)
A5: Parameter | B5: Value | E5: Notes
A6: gp_default_apec | B6: 0.45 | E6: Default GP markup for APEC quotes.
A7: gp_default_geo | B7: 0.3 | E7: Default GP markup for GEO quotes.
A9: PROFIT CALCULATOR — INPUTS (change these to model a quote)
A10: Field | B10: Value | E10: Notes
A11: company | B11: APEC | E11: APEC or GEO
A12: dispensers | B12: 4 | E12: 2 to 10
A13: canopy_type | B13: Dive-in | E13: Dive-in / Stacked / In-line
A14: column_arrangement | B14: Single | E14: Single or Double (Dive-in only)
A15: branded | B15: No | E15: Yes or No
A16: brand | E16: Brand name (used if branded=Yes)
A17: include_mid | B17: No | E17: Yes or No
A18: mid_brand | E18: MID/price-sign brand (used if include_mid=Yes)
A19: state | B19: GA | E19: Customer state — for MID labor lookup
A20: tax_rate | B20: 0.0825 | E20: Override Settings default if needed
A22: DERIVED VALUES
A23: Field | B23: Value | E23: Formula notes
A24: gp_rate (auto) | B24: =IF(B11="APEC", B6, B7)
A25: width | B25: =IF(B13="Stacked", 2*Settings!B5 + (B12/2 - 1)*Settings!B7, IF(B13="In-line", 2*Settings!B5 + (B12-1)*Settings!B8, 2*Settings!B5 + (B12-1)*Settings!B6))
A26: depth | B26: =IF(B13="Stacked", Settings!B10, IF(B13="In-line", Settings!B11, Settings!B9))
A27: columns | B27: =IF(AND(B13="Dive-in", B14="Double"), B12*2, B12)
A28: acm_panels | B28: =CEILING((2*B25 + 2*B26)/Settings!B12, 1)
A29: base_labor_days | B29: =VLOOKUP(B12, Labor_Days!A3:B11, 2, FALSE())
A32: LINE-BY-LINE ($) Selling | True Cost | Profit
A33: Line item | B33: Selling | C33: True cost | D33: Profit | E33: Notes
A34: ACM | B34: =IF(B15="Yes", 0, B28*Material_Rates!B3) | C34: =IF(B15="Yes", 0, B28*Material_Rates!C3) | D34: =B34-C34 | E34: Not charged when Branded
A35: Steel — 1st set | B35: =B12*Material_Rates!B4 | C35: =B12*Material_Rates!C4 | D35: =B35-C35 | E35: Per dispenser × $4k
A36: Steel — 2nd set | B36: =IF(AND(B13="Dive-in", B14="Double"), B12*Material_Rates!B5, 0) | C36: =IF(AND(B13="Dive-in", B14="Double"), B12*Material_Rates!C5, 0) | D36: =B36-C36 | E36: Double-col Dive-in only; AT COST (no markup)
A37: Decking | B37: =B27*Material_Rates!B6 | C37: =B27*Material_Rates!C6 | D37: =B37-C37 | E37: Per column
A38: Lights | B38: =B12*4*Material_Rates!B7 | C38: =B12*4*Material_Rates!C7 | D38: =B38-C38 | E38: Dispensers × 4 × unit price
A39: MISC base | B39: =IF(B27<=4, MISC_Tiers!C3, IF(B27<=8, MISC_Tiers!C4, MISC_Tiers!C5)) | C39: =IF(B27<=4, MISC_Tiers!D3, IF(B27<=8, MISC_Tiers!D4, MISC_Tiers!D5)) | D39: =B39-C39 | E39: Tiered by column count
A40: Shipping & handling | B40: =IF(B15="Yes", Settings!B20, 0) | C40: =IF(B15="Yes", Settings!C20, 0) | D40: =B40-C40 | E40: $3,500 if branded; AT COST
A41: Brand imaging material | B41: =IF(B15="Yes", IFERROR(INDEX(Brand_Imaging!B3:J9, MATCH(B16, Brand_Imaging!A3:A9, 0), B12-1), 0), 0) | C41: =IF(B15="Yes", IFERROR(INDEX(Brand_Imaging!B3:J9, MATCH(B16, Brand_Imaging!A3:A9, 0), B12-1), 0), 0) | D41: =B41-C41 | E41: Pure pass-through; selling = true cost (no profit on imaging itself)
A42: MID material | B42: =IF(B17="Yes", IFERROR(VLOOKUP(B18, MID_PriceSign!A3:C7, 2, FALSE()), 0), 0) | C42: =IF(B17="Yes", IFERROR(VLOOKUP(B18, MID_PriceSign!A3:C7, 3, FALSE()), 0), 0) | D42: =B42-C42 | E42: If MID; cheat sheet
A43: Base labor | B43: =B29*Settings!B17 | C43: =B29*Settings!B17 | D43: =B43-C43 | E43: Marked up at GP; daily rate IS true cost
A44: Branded labor adder | B44: =IF(B15="Yes", Settings!B18, 0) | C44: =IF(B15="Yes", Settings!C18, 0) | D44: =B44-C44 | E44: $2,800 if branded; AT COST
A45: 2-dispenser labor adder | B45: =IF(B12=2, Settings!B19, 0) | C45: =IF(B12=2, Settings!C19, 0) | D45: =B45-C45 | E45: $5,000 if 2 disp; AT COST
...
